Workbook

Sheet Export Worksheet
A1: SCAC | B1: ORDER_NO | C1: SHIPMENT_NO | D1: AIRWAY_BILL_NO | E1: ORDER_NO | F1: RO_ORDER_HEADER_KEY | G1: SO_ORDER_HEADER_KEY | H1: SO_Order_No
A2: UPSC | B2: Y100000650 | C2: 100003089 | D2: 1ZX4029Y7829676772 | E2: Y100000650 | F2: 20240401063104155890039 | G2: =VLOOKUP($F2,'SO and RO OH'!$A$2:$B$173,2,FALSE) -> 20240325050206149803182 | H2: =VLOOKUP($G2,Sheet1!$A$2:$B$143,2,FALSE) -> 00000783
A3: UPSC | B3: Y100000652 | C3: 100003092 | D3: 1ZX4029Y7814655027 | E3: Y100000652 | F3: 20240401112702155997281 | G3: =VLOOKUP($F3,'SO and RO OH'!$A$2:$B$173,2,FALSE) -> 20240325200705151532665 | H3: =VLOOKUP($G3,Sheet1!$A$2:$B$143,2,FALSE) -> 00000789
A4: UPSC | B4: Y100000654 | C4: 100003094 | D4: 1ZX4029Y7820211388 | E4: Y100000654 | F4: 20240401160748156028528 | G4: =VLOOKUP($F4,'SO and RO OH'!$A$2:$B$173,2,FALSE) -> 20240327202205152980635 | H4: =VLOOKUP($G4,Sheet1!$A$2:$B$143,2,FALSE) -> 00000811
A5: UPSC | B5: Y100000658 | C5: 100003109 | D5: 1ZX4029Y7801545750 | E5: Y100000658 | F5: 20240402221641156598886 | G5: =VLOOKUP($F5,'SO and RO OH'!$A$2:$B$173,2,FALSE) -> 20240329160204154721291 | H5: =VLOOKUP($G5,Sheet1!$A$2:$B$143,2,FALSE) -> 00000928
A6: UPSC | B6: Y100000662 | C6: 100003110 | D6: 1ZX4029Y7808936566 | E6: Y100000662 | F6: 20240402234913156600343 | G6: =VLOOKUP($F6,'SO and RO OH'!$A$2:$B$173,2,FALSE) -> 20240322184720143244304 | H6: =VLOOKUP($G6,Sheet1!$A$2:$B$143,2,FALSE) -> 00000678
A7: UPSC | B7: Y100000664 | C7: 100003117 | D7: 1ZX4029Y7822597147 | E7: Y100000664 | F7: 20240403162611157112173 | G7: =VLOOKUP($F7,'SO and RO OH'!$A$2:$B$173,2,FALSE) -> 20240325164705151179234 | H7: =VLOOKUP($G7,Sheet1!$A$2:$B$143,2,FALSE) -> 00000788
A8: UPSC | B8: Y100000666 | C8: 100003127 | D8: 1ZX4029Y7804384857 | E8: Y100000666 | F8: 20240404084225157505274 | G8: =VLOOKUP($F8,'SO and RO OH'!$A$2:$B$173,2,FALSE) -> 2024011908310086001794 | H8: =VLOOKUP($G8,Sheet1!$A$2:$B$143,2,FALSE) -> 55652659856
A9: UPSC | B9: Y100000668 | C9: 100003128 | D9: 1ZX4029Y7810633665 | E9: Y100000668 | F9: 20240404084623157505441 | G9: =VLOOKUP($F9,'SO and RO OH'!$A$2:$B$173,2,FALSE) -> 2024011908240086001307 | H9: =VLOOKUP($G9,Sheet1!$A$2:$B$143,2,FALSE) -> 55651484826
A10: UPSC | B10: Y100000669 | C10: 100003143 | D10: 1ZX4029Y7814897730 | E10: Y100000669 | F10: 20240405123749158191783 | G10: =VLOOKUP($F10,'SO and RO OH'!$A$2:$B$173,2,FALSE) -> 2024020711360090782485 | H10: =VLOOKUP($G10,Sheet1!$A$2:$B$143,2,FALSE) -> 60443657759
A11: UPSC | B11: Y100000670 | C11: 100003155 | D11: 1ZX4029Y7811035425 | E11: Y100000670 | F11: 20240406112815158666460 | G11: =VLOOKUP($F11,'SO and RO OH'!$A$2:$B$173,2,FALSE) -> 20240401143704156026784 | H11: =VLOOKUP($G11,Sheet1!$A$2:$B$143,2,FALSE) -> 00000841
A12: UPSC | B12: Y100000672 | C12: 100003169 | D12: 1ZX4029Y7836903128 | E12: Y100000672 | F12: 20240407090332159022518 | G12: =VLOOKUP($F12,'SO and RO OH'!$A$2:$B$173,2,FALSE) -> 20240405104704158119261 | H12: =VLOOKUP($G12,Sheet1!$A$2:$B$143,2,FALSE) -> 00000971
A13: UPSC | B13: Y100000673 | C13: 100003180 | D13: 1ZX4029Y7831376001 | E13: Y100000673 | F13: 20240408101800159527124 | G13: =VLOOKUP($F13,'SO and RO OH'!$A$2:$B$173,2,FALSE) -> 20240328100205153021979 | H13: =VLOOKUP($G13,Sheet1!$A$2:$B$143,2,FALSE) -> 00000913
... A156: UPSC | B156: Y100000916 | C156: 100004677 | D156: 1ZX4029Y7816766494 | E156: Y100000916 | F156: 20240718120154206343682 | G156: =VLOOKUP($F156,'SO and RO OH'!$A$2:$B$173,2,FALSE) -> 20240627201947198064509 | H156: =VLOOKUP($G156,Sheet1!$A$2:$B$143,2,FALSE) -> 00002884

Sheet SO and RO OH
A1: RO_ORDER_HEADER_KEY | B1: DERIVED_FROM_ORDER_HEADER_KEY | D1: ORDER_HEADER_KEY | E1: ORDER_NO
A2: 20240718074938206234995 | B2: 20240630125945199230870 | D2: 20240630125945199230870 | E2: 00002953 | F2: =IF($B2=$D2,1,0) -> 1
A3: 20240713110808203917514 | B3: 20240704231445200841563 | D3: 20240704231445200841563 | E3: 00003045 | F3: =IF($B3=$D3,1,0) -> 1
A4: 20240716010421205014214 | B4: 20240630150446199234307 | D4: 20240630150446199234307 | E4: 00002954 | F4: =IF($B4=$D4,1,0) -> 1
A5: 20240710100526202958247 | B5: 20240626233945197654171 | D5: 20240626233945197654171 | E5: 00002929 | F5: =IF($B5=$D5,1,0) -> 1
A6: 20240718120154206343682 | B6: 20240627201947198064509 | D6: 20240627201947198064509 | E6: 00002884 | F6: =IF($B6=$D6,1,0) -> 1
A7: 20240717181023205866403 | B7: 20240710104908203018039 | D7: 20240710104908203018039 | E7: 00003147 | F7: =IF($B7=$D7,1,0) -> 1
A8: 20240717181006205866146 | B8: 20240710104908203018039 | D8: 20240710104908203018039 | E8: 00003147 | F8: =IF($B8=$D8,1,0) -> 1
A9: 20240717180951205866100 | B9: 20240710104908203018039 | D9: 20240710104908203018039 | E9: 00003147 | F9: =IF($B9=$D9,1,0) -> 1
A10: 20240712190246203833519 | B10: 20240705140948201256147 | D10: 20240705140948201256147 | E10: 00002998 | F10: =IF($B10=$D10,1,0) -> 1
A11: 20240711110550203503770 | B11: 20240701233945199614714 | D11: 20240701233945199614714 | E11: 00002964 | F11: =IF($B11=$D11,1,0) -> 1
A12: 20240714162739204597609 | B12: 20240706110945201614530 | D12: 20240706110945201614530 | E12: 00003057 | F12: =IF($B12=$D12,1,0) -> 1
A13: 20240711111315203504166 | B13: 20240620124233195110441 | D13: 20240620124233195110441 | E13: 00002684 | F13: =IF($B13=$D13,1,0) -> 1
... A59: 20240613060856191996396 | B59: 20240319142031134934708 | D59: 20240319142031134934708 | E59: 00000480 | F59: =IF($B59=$D59,1,0) -> 1
A60: 20240613014023191960299 | B60: 20240524145703183503800 | F60: =IF($B60=$D60,1,0) -> 0
A61: 20240601141534187126769 | B61: 20240522062943182217028 | D61: 20240522062943182217028 | E61: 00002176 | F61: =IF($B61=$D61,1,0) -> 1
A62: 20240602181919187530612 | B62: 20240525173733183907371 | D62: 20240525173733183907371 | E62: 00002201 | F62: =IF($B62=$D62,1,0) -> 1
A63: 20240609205808190626992 | B63: 20240602222733187540068 | D63: 20240602222733187540068 | E63: 00002368 | F63: =IF($B63=$D63,1,0) -> 1
A64: 20240608172855190216332 | B64: 20240605125733188954062 | D64: 20240605125733188954062 | E64: 00002378 | F64: =IF($B64=$D64,1,0) -> 1
A65: 20240529000830185303085 | B65: 20240511153443176458216 | D65: 20240511153443176458216 | E65: 00002017 | F65: =IF($B65=$D65,1,0) -> 1
A66: 20240528065733185119328 | B66: 20240504072917172327542 | D66: 20240504072917172327542 | E66: 00001533 | F66: =IF($B66=$D66,1,0) -> 1
A67: 20240528065924185119366 | B67: 20240413121616162063114 | D67: 20240413121616162063114 | E67: 00001044 | F67: =IF($B67=$D67,1,0) -> 1
A68: 20240605100127188785873 | B68: 20240502213416171504625 | D68: 20240502213416171504625 | E68: 00001611 | F68: =IF($B68=$D68,1,0) -> 1
A69: 20240528223622185296763 | B69: 20240520233443181524769 | D69: 20240520233443181524769 | E69: 00002257 | F69: =IF($B69=$D69,1,0) -> 1
A70: 20240527014532184364975 | B70: 20240513003443177221889 | D70: 20240513003443177221889 | E70: 00002044 | F70: =IF($B70=$D70,1,0) -> 1
A71: 20240422011905166277782 | B71: 20240407223706159163422 | D71: 20240407223706159163422 | E71: 00000902 | F71: =IF($B71=$D71,1,0) -> 1
A72: 20240603052604187665750 | B72: 20240413121616162063114 | F72: =IF($B72=$D73,1,0) -> 0
A73: 20240519011302180546595 | B73: 20240510145442175971532 | D73: 20240510145442175971532 | E73: 00001762 | F73: =IF($B73=$D73,1,0) -> 1
A74: 20240531175619186736824 | B74: 20240528145233185278512 | D74: 20240528145233185278512 | E74: 00002451 | F74: =IF($B74=$D74,1,0) -> 1
A75: 20240522212427182450670 | B75: 20240515141443178804574 | D75: 20240311091619117758874 | E75: 67404985934 | F75: =IF($B75=$D75,1,0) -> 0
A76: 20240521081321181716377 | B76: 20240311091619117758874 | D76: 20240311091619117758874 | E76: 00001977 | F76: =IF($B76=$D76,1,0) -> 0
A77: 20240522000838181907072 | B77: 20240512213943177214999 | D77: 20240512213943177214999 | E77: 00001934 | F77: =IF($B77=$D77,1,0) -> 1
A78: 20240523164214182974581 | B78: 20240516215945179444583 | D78: 20240516215945179444583 | E78: 00002116 | F78: =IF($B78=$D78,1,0) -> 1
A79: 20240519101549180809334 | B79: 20240510165942176001719 | D79: 20240510165942176001719 | E79: 00001773 | F79: =IF($B79=$D79,1,0) -> 1
A80: 20240523200444182990141 | B80: 20240519150943180964326 | D80: 20240519150943180964326 | E80: 00002232 | F80: =IF($B80=$D80,1,0) -> 1
A81: 20240528181740185286983 | B81: 20240521092944181721836 | D81: 20240521092944181721836 | E81: 00002275 | F81: =IF($B81=$D81,1,0) -> 1
A82: 20240521073317181708554 | B82: 20240411114704161572158 | D82: 20240411114704161572158 | E82: 00001133 | F82: =IF($B82=$D82,1,0) -> 1
A83: 20240517014401179497707 | B83: 20240507190416174630896 | D83: 20240507190416174630896 | E83: 00001687 | F83: =IF($B83=$D83,1,0) -> 1
A84: 20240516173019179423274 | B84: 20240429143419170027145 | D84: 20240429143419170027145 | E84: 00001391 | F84: =IF($B84=$D84,1,0) -> 1
... A153: 20240405123749158191783 | B153: 2024020711360090782485 | D153: 20240325050206149803182 | E153: 00000783 | F153: =IF($B153=$D153,1,0) -> 0
...

Sheet Sheet1
A1: ORDER_HEADER_KEY | B1: ORDER_NO
A2: 20240630125945199230870 | B2: 00002953
A3: 20240704231445200841563 | B3: 00003045
A4: 20240630150446199234307 | B4: 00002954
A5: 20240626233945197654171 | B5: 00002929
A6: 20240627201947198064509 | B6: 00002884
A7: 20240710104908203018039 | B7: 00003147
A8: 20240705140948201256147 | B8: 00002998
A9: 20240701233945199614714 | B9: 00002964
A10: 20240706110945201614530 | B10: 00003057
A11: 20240620124233195110441 | B11: 00002684
A12: 2023122814190080269164 | B12: 51876761651
... A143: 20240329160204154721291 | B143: 00000928
