Workbook

Sheet Sheet1
A1: LocationCode | B1: ItemCode | C1: LotNumber | D1: New location code | E1: Item ID | F1: Code | G1: lot | H1: posting classification | I1: product code | K1: <API FlowName="IBD_UpdateInventory"><Input> <InventorySnapShot InventoryFeedType="0" OrganizationCode="TITAN_GCC"> <ShipNode ShipNode=" | L1: "> <Item ItemID=" | M1: " LotNumber=" | N1: " CFAProductCode=" | O1: " ProductCode=" | P1: "> <SupplyDetails Quantity="1"/> </Item> </ShipNode> </InventorySnapShot> </Input></API>
B2: EL0063OFAAAB02 | C2: 2JA000004 | D2: XDB | E2: =_xlfn.CONCAT($B2,$C2) -> EL0063OFAAAB022JA000004 | F2: EL0104SQAABAPL | G2: 2JA000004 | H2: 72 | I2: O | K2: =_xlfn.CONCAT($K$1,$D2,$L$1,$F2,$M$1,$G2,$N$1,$H2,$O$1,$I2,$P$1) -> <API FlowName="IBD_UpdateInventory"><Input> <InventorySnapShot InventoryFeedType="0" OrganizationCode="TITAN_GCC"> <ShipNode ShipNode="XDB"> <Item ItemID="EL0104SQAABAPL" LotNumber="2JA000004" CFAProductCode="72" ProductCode="O"> <SupplyDetails Quantity="1"/> </Item> </ShipNode> </InventorySnapShot> </Input></API>
B3: EL0063OKAAAA04 | C3: 2JA000013 | D3: XDB | E3: =_xlfn.CONCAT($B3,$C3) -> EL0063OKAAAA042JA000013 | F3: EL0063OKAAAA04 | G3: 2JA000013 | H3: 72 | I3: O | K3: =_xlfn.CONCAT($K$1,$D3,$L$1,$F3,$M$1,$G3,$N$1,$H3,$O$1,$I3,$P$1) -> <API FlowName="IBD_UpdateInventory"><Input> <InventorySnapShot InventoryFeedType="0" OrganizationCode="TITAN_GCC"> <ShipNode ShipNode="XDB"> <Item ItemID="EL0063OKAAAA04" LotNumber="2JA000013" CFAProductCode="72" ProductCode="O"> <SupplyDetails Quantity="1"/> </Item> </ShipNode> </InventorySnapShot> </Input></API>
B4: EL0063OLAAAC02 | C4: 2JA000003 | D4: XDB | E4: =_xlfn.CONCAT($B4,$C4) -> EL0063OLAAAC022JA000003 | F4: EL0063OLAAAC02 | G4: 2JA000003 | H4: 72 | I4: O | K4: =_xlfn.CONCAT($K$1,$D4,$L$1,$F4,$M$1,$G4,$N$1,$H4,$O$1,$I4,$P$1) -> <API FlowName="IBD_UpdateInventory"><Input> <InventorySnapShot InventoryFeedType="0" OrganizationCode="TITAN_GCC"> <ShipNode ShipNode="XDB"> <Item ItemID="EL0063OLAAAC02" LotNumber="2JA000003" CFAProductCode="72" ProductCode="O"> <SupplyDetails Quantity="1"/> </Item> </ShipNode> </InventorySnapShot> </Input></API>
B5: EL0063OXAAAC04 | C5: 2JA000005 | D5: XDB | E5: =_xlfn.CONCAT($B5,$C5) -> EL0063OXAAAC042JA000005 | F5: EL0063OXAAAC04 | G5: 2JA000005 | H5: 72 | I5: O | K5: =_xlfn.CONCAT($K$1,$D5,$L$1,$F5,$M$1,$G5,$N$1,$H5,$O$1,$I5,$P$1) -> <API FlowName="IBD_UpdateInventory"><Input> <InventorySnapShot InventoryFeedType="0" OrganizationCode="TITAN_GCC"> <ShipNode ShipNode="XDB"> <Item ItemID="EL0063OXAAAC04" LotNumber="2JA000005" CFAProductCode="72" ProductCode="O"> <SupplyDetails Quantity="1"/> </Item> </ShipNode> </InventorySnapShot> </Input></API>
B6: EL0064OFAAAB02 | C6: 2JA000004 | D6: XDB | E6: =_xlfn.CONCAT($B6,$C6) -> EL0064OFAAAB022JA000004 | F6: EL0064OFAAAB02 | G6: 2JA000004 | H6: 72 | I6: O | K6: =_xlfn.CONCAT($K$1,$D6,$L$1,$F6,$M$1,$G6,$N$1,$H6,$O$1,$I6,$P$1) -> <API FlowName="IBD_UpdateInventory"><Input> <InventorySnapShot InventoryFeedType="0" OrganizationCode="TITAN_GCC"> <ShipNode ShipNode="XDB"> <Item ItemID="EL0064OFAAAB02" LotNumber="2JA000004" CFAProductCode="72" ProductCode="O"> <SupplyDetails Quantity="1"/> </Item> </ShipNode> </InventorySnapShot> </Input></API>
B7: EL0060SAAAGAPL | C7: 2JA000028 | D7: XDK | E7: =_xlfn.CONCAT($B7,$C7) -> EL0060SAAAGAPL2JA000028 | F7: EL0060SAAAGAPL | G7: 2JA000028 | H7: 78 | I7: S | K7: =_xlfn.CONCAT($K$1,$D7,$L$1,$F7,$M$1,$G7,$N$1,$H7,$O$1,$I7,$P$1) -> <API FlowName="IBD_UpdateInventory"><Input> <InventorySnapShot InventoryFeedType="0" OrganizationCode="TITAN_GCC"> <ShipNode ShipNode="XDK"> <Item ItemID="EL0060SAAAGAPL" LotNumber="2JA000028" CFAProductCode="78" ProductCode="S"> <SupplyDetails Quantity="1"/> </Item> </ShipNode> </InventorySnapShot> </Input></API>
B8: EL0063OJAAAB02 | C8: 2JA000010 | D8: XDK | E8: =_xlfn.CONCAT($B8,$C8) -> EL0063OJAAAB022JA000010 | F8: EL0063OJAAAB02 | G8: 2JA000010 | H8: 72 | I8: O | K8: =_xlfn.CONCAT($K$1,$D8,$L$1,$F8,$M$1,$G8,$N$1,$H8,$O$1,$I8,$P$1) -> <API FlowName="IBD_UpdateInventory"><Input> <InventorySnapShot InventoryFeedType="0" OrganizationCode="TITAN_GCC"> <ShipNode ShipNode="XDK"> <Item ItemID="EL0063OJAAAB02" LotNumber="2JA000010" CFAProductCode="72" ProductCode="O"> <SupplyDetails Quantity="1"/> </Item> </ShipNode> </InventorySnapShot> </Input></API>
B9: EL0104SQAABAPL | C9: 3IH000074 | D9: XDK | E9: =_xlfn.CONCAT($B9,$C9) -> EL0104SQAABAPL3IH000074 | F9: EL0104SQAABAPL | G9: 3IH000074 | H9: 78 | I9: S | K9: =_xlfn.CONCAT($K$1,$D9,$L$1,$F9,$M$1,$G9,$N$1,$H9,$O$1,$I9,$P$1) -> <API FlowName="IBD_UpdateInventory"><Input> <InventorySnapShot InventoryFeedType="0" OrganizationCode="TITAN_GCC"> <ShipNode ShipNode="XDK"> <Item ItemID="EL0104SQAABAPL" LotNumber="3IH000074" CFAProductCode="78" ProductCode="S"> <SupplyDetails Quantity="1"/> </Item> </ShipNode> </InventorySnapShot> </Input></API>
B10: EL0178SGAABA12 | C10: 2JA000057 | D10: XDK | E10: =_xlfn.CONCAT($B10,$C10) -> EL0178SGAABA122JA000057 | F10: EL0178SGAABA12 | G10: 2JA000057 | H10: 78 | I10: S | K10: =_xlfn.CONCAT($K$1,$D10,$L$1,$F10,$M$1,$G10,$N$1,$H10,$O$1,$I10,$P$1) -> <API FlowName="IBD_UpdateInventory"><Input> <InventorySnapShot InventoryFeedType="0" OrganizationCode="TITAN_GCC"> <ShipNode ShipNode="XDK"> <Item ItemID="EL0178SGAABA12" LotNumber="2JA000057" CFAProductCode="78" ProductCode="S"> <SupplyDetails Quantity="1"/> </Item> </ShipNode> </InventorySnapShot> </Input></API>
B11: EL0819OIAABA02 | C11: 2JA000007 | D11: XDK | E11: =_xlfn.CONCAT($B11,$C11) -> EL0819OIAABA022JA000007 | F11: EL0819OIAABA02 | G11: 2JA000007 | H11: 72 | I11: O | K11: =_xlfn.CONCAT($K$1,$D11,$L$1,$F11,$M$1,$G11,$N$1,$H11,$O$1,$I11,$P$1) -> <API FlowName="IBD_UpdateInventory"><Input> <InventorySnapShot InventoryFeedType="0" OrganizationCode="TITAN_GCC"> <ShipNode ShipNode="XDK"> <Item ItemID="EL0819OIAABA02" LotNumber="2JA000007" CFAProductCode="72" ProductCode="O"> <SupplyDetails Quantity="1"/> </Item> </ShipNode> </InventorySnapShot> </Input></API>
B12: EL0009SXAABA12 | C12: 2JA000027 | D12: XAH | E12: =_xlfn.CONCAT($B12,$C12) -> EL0009SXAABA122JA000027 | F12: EL0009SXAABA12 | G12: 2JA000027 | H12: 78 | I12: S | K12: =_xlfn.CONCAT($K$1,$D12,$L$1,$F12,$M$1,$G12,$N$1,$H12,$O$1,$I12,$P$1) -> <API FlowName="IBD_UpdateInventory"><Input> <InventorySnapShot InventoryFeedType="0" OrganizationCode="TITAN_GCC"> <ShipNode ShipNode="XAH"> <Item ItemID="EL0009SXAABA12" LotNumber="2JA000027" CFAProductCode="78" ProductCode="S"> <SupplyDetails Quantity="1"/> </Item> </ShipNode> </InventorySnapShot> </Input></API>
B13: EL0063ODAAAB04 | C13: 2JA000004 | D13: XAH | E13: =_xlfn.CONCAT($B13,$C13) -> EL0063ODAAAB042JA000004 | F13: EL0063ODAAAB04 | G13: 2JA000004 | H13: 72 | I13: O | K13: =_xlfn.CONCAT($K$1,$D13,$L$1,$F13,$M$1,$G13,$N$1,$H13,$O$1,$I13,$P$1) -> <API FlowName="IBD_UpdateInventory"><Input> <InventorySnapShot InventoryFeedType="0" OrganizationCode="TITAN_GCC"> <ShipNode ShipNode="XAH"> <Item ItemID="EL0063ODAAAB04" LotNumber="2JA000004" CFAProductCode="72" ProductCode="O"> <SupplyDetails Quantity="1"/> </Item> </ShipNode> </InventorySnapShot> </Input></API>
... B16: EL0063SLAABA13 | C16: 2JA000037 | D16: XAH | E16: =_xlfn.CONCAT($B16,$C16) -> EL0063SLAABA132JA000037 | F16: EL0063SLAABA13 | G16: 2JA000037 | H16: 78 | I16: S | K16: =_xlfn.CONCAT($K$1,$D16,$L$1,$F16,$M$1,$G16,$N$1,$H16,$O$1,$I16,$P$1) -> <API FlowName="IBD_UpdateInventory"><Input> <InventorySnapShot InventoryFeedType="0" OrganizationCode="TITAN_GCC"> <ShipNode ShipNode="XAH"> <Item ItemID="EL0063SLAABA13" LotNumber="2JA000037" CFAProductCode="78" ProductCode="S"> <SupplyDetails Quantity="1"/> </Item> </ShipNode> </InventorySnapShot> </Input></API>
E17: =_xlfn.CONCAT($B17,$C17) | F17: =VLOOKUP(E17,Sheet2!$B$2:$F$67,{2,3,4,5},FALSE) | K17: =_xlfn.CONCAT($K$1,$D17,$L$1,$F17,$M$1,$G17,$N$1,$H17,$O$1,$I17,$P$1) -> <API FlowName="IBD_UpdateInventory"><Input> <InventorySnapShot InventoryFeedType="0" OrganizationCode="TITAN_GCC"> <ShipNode ShipNode=""> <Item ItemID="=VLOOKUP(E17,Sheet2!$B$2:$F$67,{2,3,4,5},FALSE)" LotNumber="" CFAProductCode="" ProductCode=""> <SupplyDetails Quantity="1"/> </Item> </ShipNode> </InventorySnapShot> </Input></API>
E18: =_xlfn.CONCAT($B18,$C18) | F18: =vlookup(E18,'Sheet2'!B2:F16,{2,3,4,5},FALSE) | K18: =_xlfn.CONCAT($K$1,$D18,$L$1,$F18,$M$1,$G18,$N$1,$H18,$O$1,$I18,$P$1) -> <API FlowName="IBD_UpdateInventory"><Input> <InventorySnapShot InventoryFeedType="0" OrganizationCode="TITAN_GCC"> <ShipNode ShipNode=""> <Item ItemID="=vlookup(E18,'Sheet2'!B2:F16,{2,3,4,5},FALSE)" LotNumber="" CFAProductCode="" ProductCode=""> <SupplyDetails Quantity="1"/> </Item> </ShipNode> </InventorySnapShot> </Input></API>
E19: =_xlfn.CONCAT($B19,$C19) | F19: {=VLOOKUP(E19,Sheet2!$B$2:$F$67,{2,3,4,5},FALSE)} -> 0 | G19: 0 | H19: 0 | I19: 0 | K19: =_xlfn.CONCAT($K$1,$D19,$L$1,$F19,$M$1,$G19,$N$1,$H19,$O$1,$I19,$P$1) -> <API FlowName="IBD_UpdateInventory"><Input> <InventorySnapShot InventoryFeedType="0" OrganizationCode="TITAN_GCC"> <ShipNode ShipNode=""> <Item ItemID="0" LotNumber="0" CFAProductCode="0" ProductCode="0"> <SupplyDetails Quantity="1"/> </Item> </ShipNode> </InventorySnapShot> </Input></API>
E20: =_xlfn.CONCAT($B20,$C20) | F20: {=VLOOKUP(E20,Sheet2!$B$2:$F$67,{2,3,4,5},FALSE)} -> 0 | G20: 0 | H20: 0 | I20: 0 | K20: =_xlfn.CONCAT($K$1,$D20,$L$1,$F20,$M$1,$G20,$N$1,$H20,$O$1,$I20,$P$1) -> <API FlowName="IBD_UpdateInventory"><Input> <InventorySnapShot InventoryFeedType="0" OrganizationCode="TITAN_GCC"> <ShipNode ShipNode=""> <Item ItemID="0" LotNumber="0" CFAProductCode="0" ProductCode="0"> <SupplyDetails Quantity="1"/> </Item> </ShipNode> </InventorySnapShot> </Input></API>
E21: =_xlfn.CONCAT($B21,$C21) | F21: {=VLOOKUP(E21,Sheet2!$B$2:$F$67,{2,3,4,5},FALSE)} -> 0 | G21: 0 | H21: 0 | I21: 0 | K21: =_xlfn.CONCAT($K$1,$D21,$L$1,$F21,$M$1,$G21,$N$1,$H21,$O$1,$I21,$P$1) -> <API FlowName="IBD_UpdateInventory"><Input> <InventorySnapShot InventoryFeedType="0" OrganizationCode="TITAN_GCC"> <ShipNode ShipNode=""> <Item ItemID="0" LotNumber="0" CFAProductCode="0" ProductCode="0"> <SupplyDetails Quantity="1"/> </Item> </ShipNode> </InventorySnapShot> </Input></API>
E22: =_xlfn.CONCAT($B22,$C22) | F22: {=VLOOKUP(E22,Sheet2!$B$2:$F$67,{2,3,4,5},FALSE)} -> 0 | G22: 0 | H22: 0 | I22: 0 | K22: =_xlfn.CONCAT($K$1,$D22,$L$1,$F22,$M$1,$G22,$N$1,$H22,$O$1,$I22,$P$1) -> <API FlowName="IBD_UpdateInventory"><Input> <InventorySnapShot InventoryFeedType="0" OrganizationCode="TITAN_GCC"> <ShipNode ShipNode=""> <Item ItemID="0" LotNumber="0" CFAProductCode="0" ProductCode="0"> <SupplyDetails Quantity="1"/> </Item> </ShipNode> </InventorySnapShot> </Input></API>
E23: =_xlfn.CONCAT($B23,$C23) | F23: {=VLOOKUP(E23,Sheet2!$B$2:$F$67,{2,3,4,5},FALSE)} -> 0 | G23: 0 | H23: 0 | I23: 0 | K23: =_xlfn.CONCAT($K$1,$D23,$L$1,$F23,$M$1,$G23,$N$1,$H23,$O$1,$I23,$P$1) -> <API FlowName="IBD_UpdateInventory"><Input> <InventorySnapShot InventoryFeedType="0" OrganizationCode="TITAN_GCC"> <ShipNode ShipNode=""> <Item ItemID="0" LotNumber="0" CFAProductCode="0" ProductCode="0"> <SupplyDetails Quantity="1"/> </Item> </ShipNode> </InventorySnapShot> </Input></API>
E24: =_xlfn.CONCAT($B24,$C24) | F24: {=VLOOKUP(E24,Sheet2!$B$2:$F$67,{2,3,4,5},FALSE)} -> 0 | G24: 0 | H24: 0 | I24: 0 | K24: =_xlfn.CONCAT($K$1,$D24,$L$1,$F24,$M$1,$G24,$N$1,$H24,$O$1,$I24,$P$1) -> <API FlowName="IBD_UpdateInventory"><Input> <InventorySnapShot InventoryFeedType="0" OrganizationCode="TITAN_GCC"> <ShipNode ShipNode=""> <Item ItemID="0" LotNumber="0" CFAProductCode="0" ProductCode="0"> <SupplyDetails Quantity="1"/> </Item> </ShipNode> </InventorySnapShot> </Input></API>
E25: =_xlfn.CONCAT($B25,$C25) | F25: {=VLOOKUP(E25,Sheet2!$B$2:$F$67,{2,3,4,5},FALSE)} -> 0 | G25: 0 | H25: 0 | I25: 0 | K25: =_xlfn.CONCAT($K$1,$D25,$L$1,$F25,$M$1,$G25,$N$1,$H25,$O$1,$I25,$P$1) -> <API FlowName="IBD_UpdateInventory"><Input> <InventorySnapShot InventoryFeedType="0" OrganizationCode="TITAN_GCC"> <ShipNode ShipNode=""> <Item ItemID="0" LotNumber="0" CFAProductCode="0" ProductCode="0"> <SupplyDetails Quantity="1"/> </Item> </ShipNode> </InventorySnapShot> </Input></API>
E26: =_xlfn.CONCAT($B26,$C26) | F26: {=VLOOKUP(E26,Sheet2!$B$2:$F$67,{2,3,4,5},FALSE)} -> 0 | G26: 0 | H26: 0 | I26: 0 | K26: =_xlfn.CONCAT($K$1,$D26,$L$1,$F26,$M$1,$G26,$N$1,$H26,$O$1,$I26,$P$1) -> <API FlowName="IBD_UpdateInventory"><Input> <InventorySnapShot InventoryFeedType="0" OrganizationCode="TITAN_GCC"> <ShipNode ShipNode=""> <Item ItemID="0" LotNumber="0" CFAProductCode="0" ProductCode="0"> <SupplyDetails Quantity="1"/> </Item> </ShipNode> </InventorySnapShot> </Input></API>
E27: =_xlfn.CONCAT($B27,$C27) | F27: {=VLOOKUP(E27,Sheet2!$B$2:$F$67,{2,3,4,5},FALSE)} -> 0 | G27: 0 | H27: 0 | I27: 0 | K27: =_xlfn.CONCAT($K$1,$D27,$L$1,$F27,$M$1,$G27,$N$1,$H27,$O$1,$I27,$P$1) -> <API FlowName="IBD_UpdateInventory"><Input> <InventorySnapShot InventoryFeedType="0" OrganizationCode="TITAN_GCC"> <ShipNode ShipNode=""> <Item ItemID="0" LotNumber="0" CFAProductCode="0" ProductCode="0"> <SupplyDetails Quantity="1"/> </Item> </ShipNode> </InventorySnapShot> </Input></API>
E28: =_xlfn.CONCAT($B28,$C28) | F28: {=VLOOKUP(E28,Sheet2!$B$2:$F$67,{2,3,4,5},FALSE)} -> 0 | G28: 0 | H28: 0 | I28: 0 | K28: =_xlfn.CONCAT($K$1,$D28,$L$1,$F28,$M$1,$G28,$N$1,$H28,$O$1,$I28,$P$1) -> <API FlowName="IBD_UpdateInventory"><Input> <InventorySnapShot InventoryFeedType="0" OrganizationCode="TITAN_GCC"> <ShipNode ShipNode=""> <Item ItemID="0" LotNumber="0" CFAProductCode="0" ProductCode="0"> <SupplyDetails Quantity="1"/> </Item> </ShipNode> </InventorySnapShot> </Input></API>
E29: =_xlfn.CONCAT($B29,$C29) | F29: {=VLOOKUP(E29,Sheet2!$B$2:$F$67,{2,3,4,5},FALSE)} -> 0 | G29: 0 | H29: 0 | I29: 0 | K29: =_xlfn.CONCAT($K$1,$D29,$L$1,$F29,$M$1,$G29,$N$1,$H29,$O$1,$I29,$P$1) -> <API FlowName="IBD_UpdateInventory"><Input> <InventorySnapShot InventoryFeedType="0" OrganizationCode="TITAN_GCC"> <ShipNode ShipNode=""> <Item ItemID="0" LotNumber="0" CFAProductCode="0" ProductCode="0"> <SupplyDetails Quantity="1"/> </Item> </ShipNode> </InventorySnapShot> </Input></API>
E30: =_xlfn.CONCAT($B30,$C30) | F30: {=VLOOKUP(E30,Sheet2!$B$2:$F$67,{2,3,4,5},FALSE)} -> 0 | G30: 0 | H30: 0 | I30: 0 | K30: =_xlfn.CONCAT($K$1,$D30,$L$1,$F30,$M$1,$G30,$N$1,$H30,$O$1,$I30,$P$1) -> <API FlowName="IBD_UpdateInventory"><Input> <InventorySnapShot InventoryFeedType="0" OrganizationCode="TITAN_GCC"> <ShipNode ShipNode=""> <Item ItemID="0" LotNumber="0" CFAProductCode="0" ProductCode="0"> <SupplyDetails Quantity="1"/> </Item> </ShipNode> </InventorySnapShot> </Input></API>
... E39: =_xlfn.CONCAT($B39,$C39) | F39: {=VLOOKUP(E39,Sheet2!$B$2:$F$67,{2,3,4,5},FALSE)} -> 0 | G39: 0 | H39: 0 | I39: 0 | K39: =_xlfn.CONCAT($K$1,$D39,$L$1,$F39,$M$1,$G39,$N$1,$H39,$O$1,$I39,$P$1) -> <API FlowName="IBD_UpdateInventory"><Input> <InventorySnapShot InventoryFeedType="0" OrganizationCode="TITAN_GCC"> <ShipNode ShipNode=""> <Item ItemID="0" LotNumber="0" CFAProductCode="0" ProductCode="0"> <SupplyDetails Quantity="1"/> </Item> </ShipNode> </InventorySnapShot> </Input></API>
E40: =_xlfn.CONCAT($B40,$C40)
E41: =_xlfn.CONCAT($B41,$C41)
E42: =_xlfn.CONCAT($B42,$C42)
E44: =_xlfn.CONCAT($B44,$C44)
E45: =_xlfn.CONCAT($B45,$C45)
E46: =_xlfn.CONCAT($B46,$C46)
E47: =_xlfn.CONCAT($B47,$C47)
E48: =_xlfn.CONCAT($B48,$C48)
E49: =_xlfn.CONCAT($B49,$C49)
E50: =_xlfn.CONCAT($B50,$C50)
E51: =_xlfn.CONCAT($B51,$C51)
...

Sheet Sheet2
A1: Item ID | C1: Code | D1: lot | E1: posting classification | F1: product code
A2: EL0009SXAABA122JA000027 | B2: =TRIM($A2) -> EL0009SXAABA122JA000027 | C2: EL0063OJAAAB02 | D2: 2JA000010 | E2: 72 | F2: O
A3: EL0060SAAAGAPL2JA000028 | B3: =TRIM($A3) -> EL0060SAAAGAPL2JA000028 | C3: EL0819OIAABA02 | D3: 2JA000007 | E3: 72 | F3: O
A4: EL0063ODAAAB042JA000004 | B4: =TRIM($A4) -> EL0063ODAAAB042JA000004 | C4: EL0060SAAAGAPL | D4: 2JA000028 | E4: 78 | F4: S
A5: EL0063OFAAAB022JA000004 | B5: =TRIM($A5) -> EL0063OFAAAB022JA000004 | C5: EL0104SQAABAPL | D5: 3IH000074 | E5: 78 | F5: S
A6: EL0063OJAAAB022JA000010 | B6: =TRIM($A6) -> EL0063OJAAAB022JA000010 | C6: EL0178SGAABA12 | D6: 2JA000057 | E6: 78 | F6: S
A7: EL0063OJAAAB042JA000005 | B7: =TRIM($A7) -> EL0063OJAAAB042JA000005 | C7: EL0063OFAAAB02 | D7: 2JA000004 | E7: 72 | F7: O
A8: EL0063OKAAAA042JA000013 | B8: =TRIM($A8) -> EL0063OKAAAA042JA000013 | C8: EL0063OXAAAC04 | D8: 2JA000005 | E8: 72 | F8: O
A9: EL0063OLAAAC022JA000003 | B9: =TRIM($A9) -> EL0063OLAAAC022JA000003 | C9: EL0063OJAAAB04 | D9: 2JA000005 | E9: 72 | F9: O
A10: EL0063OXAAAC042JA000003 | B10: =TRIM($A10) -> EL0063OXAAAC042JA000003 | C10: EL0063OKAAAA04 | D10: 2JA000013 | E10: 72 | F10: O
A11: EL0063OXAAAC042JA000005 | B11: =TRIM($A11) -> EL0063OXAAAC042JA000005 | C11: EL0063OXAAAC04 | D11: 2JA000003 | E11: 72 | F11: O
A12: EL0063SLAABA132JA000037 | B12: =TRIM($A12) -> EL0063SLAABA132JA000037 | C12: EL0063ODAAAB04 | D12: 2JA000004 | E12: 72 | F12: O
A13: EL0064OFAAAB022JA000004 | B13: =TRIM($A13) -> EL0064OFAAAB022JA000004 | C13: EL0009SXAABA12 | D13: 2JA000027 | E13: 78 | F13: S
... A16: EL0819OIAABA022JA000007 | B16: =TRIM($A16) -> EL0819OIAABA022JA000007 | C16: EL0064OFAAAB02 | D16: 2JA000004 | E16: 72 | F16: O
B17: =TRIM($A17)
B18: =TRIM($A18)
B19: =TRIM($A19)
B20: =TRIM($A20)
B21: =TRIM($A21)
B22: =TRIM($A22)
B23: =TRIM($A23)
B24: =TRIM($A24)
B25: =TRIM($A25)
B26: =TRIM($A26)
B27: =TRIM($A27)
B28: =TRIM($A28)
... B67: =TRIM($A67)

Sheet Sheet3
A1: ItemCode | B1: LotNumber | C1: New location code | D1: Item ID
A2: UL1519CMNGLA00 | B2: 2OXNJ0038 | C2: XTH | D2: =_xlfn.CONCAT($A2,$B2) -> UL1519CMNGLA002OXNJ0038 | E2: {=VLOOKUP($D2,$A$90:$C$155,{2,3},FALSE)} -> XTH | F2: 1 | H2: =IF($C2=$E2,TRUE,FALSE) -> TRUE
A3: UL1919CEFIAA00 | B3: 2EE000002 | C3: XTH | D3: =_xlfn.CONCAT($A3,$B3) -> UL1919CEFIAA002EE000002 | E3: {=VLOOKUP($D3,$A$90:$C$155,{2,3},FALSE)} -> XTH | F3: 1 | H3: =IF($C3=$E3,TRUE,FALSE) -> TRUE
A4: UL1920SDCAGA00 | B4: 2JA000015 | C4: XTD | D4: =_xlfn.CONCAT($A4,$B4) -> UL1920SDCAGA002JA000015 | E4: {=VLOOKUP($D4,$A$90:$C$155,{2,3},FALSE)} -> XTD | F4: 1 | H4: =IF($C4=$E4,TRUE,FALSE) -> TRUE
A5: UL1920SDDAGA00 | B5: 2JA000014 | C5: XTD | D5: =_xlfn.CONCAT($A5,$B5) -> UL1920SDDAGA002JA000014 | E5: {=VLOOKUP($D5,$A$90:$C$155,{2,3},FALSE)} -> XTD | F5: 1 | H5: =IF($C5=$E5,TRUE,FALSE) -> TRUE
A6: UL2617FFASAA00 | B6: 2ED000004 | C6: XCG | D6: =_xlfn.CONCAT($A6,$B6) -> UL2617FFASAA002ED000004 | E6: {=VLOOKUP($D6,$A$90:$C$155,{2,3},FALSE)} -> XCG | F6: 1 | H6: =IF($C6=$E6,TRUE,FALSE) -> TRUE
A7: UL2617FFFSAA00 | B7: 2ED000003 | C7: XCG | D7: =_xlfn.CONCAT($A7,$B7) -> UL2617FFFSAA002ED000003 | E7: {=VLOOKUP($D7,$A$90:$C$155,{2,3},FALSE)} -> XCG | F7: 1 | H7: =IF($C7=$E7,TRUE,FALSE) -> TRUE
A8: UL1047FBWNAA04 | B8: 3IH000001 | C8: XTH | D8: =_xlfn.CONCAT($A8,$B8) -> UL1047FBWNAA043IH000001 | E8: {=VLOOKUP($D8,$A$90:$C$155,{2,3},FALSE)} -> XTH | F8: 1 | H8: =IF($C8=$E8,TRUE,FALSE) -> TRUE
A9: UL0769FGATAA04 | B9: 3IH000002 | C9: XTH | D9: =_xlfn.CONCAT($A9,$B9) -> UL0769FGATAA043IH000002 | E9: {=VLOOKUP($D9,$A$90:$C$155,{2,3},FALSE)} -> XTH | F9: 1 | H9: =IF($C9=$E9,TRUE,FALSE) -> TRUE
A10: UL0859DBAABA31 | B10: 2JA000003 | C10: XTD | D10: =_xlfn.CONCAT($A10,$B10) -> UL0859DBAABA312JA000003 | E10: {=VLOOKUP($D10,$A$90:$C$155,{2,3},FALSE)} -> XTD | F10: 1 | H10: =IF($C10=$E10,TRUE,FALSE) -> TRUE
A11: UL1002FHCSAA04 | B11: 3IH000001 | C11: XTD | D11: =_xlfn.CONCAT($A11,$B11) -> UL1002FHCSAA043IH000001 | E11: {=VLOOKUP($D11,$A$90:$C$155,{2,3},FALSE)} -> XTD | F11: 1 | H11: =IF($C11=$E11,TRUE,FALSE) -> TRUE
A12: UL1002FILUAA02 | B12: 2JA000005 | C12: XCG | D12: =_xlfn.CONCAT($A12,$B12) -> UL1002FILUAA022JA000005 | E12: {=VLOOKUP($D12,$A$90:$C$155,{2,3},FALSE)} -> XCG | F12: 1 | H12: =IF($C12=$E12,TRUE,FALSE) -> TRUE
A13: UL1002FIZMAA02 | B13: 1BL000004 | C13: XCG | D13: =_xlfn.CONCAT($A13,$B13) -> UL1002FIZMAA021BL000004 | E13: {=VLOOKUP($D13,$A$90:$C$155,{2,3},FALSE)} -> XCG | F13: 1 | H13: =IF($C13=$E13,TRUE,FALSE) -> TRUE
... A67: UP5060VKWR2AP5 | B67: 1BL000002 | C67: XCG | D67: =_xlfn.CONCAT($A67,$B67) -> UP5060VKWR2AP51BL000002 | E67: {=VLOOKUP($D67,$A$90:$C$155,{2,3},FALSE)} -> XCG | F67: 1 | H67: =IF($C67=$E67,TRUE,FALSE) -> TRUE
A90: UL0495FMAOAA122JA000013 | B90: XTH | C90: 1 | D90: =TRIM($A90) -> UL0495FMAOAA122JA000013
A91: UL0553VKAR2A022BA000003 | B91: XTH | C91: 1 | D91: =TRIM($A91) -> UL0553VKAR2A022BA000003
A92: UL0769FGATAA043IH000002 | B92: XTH | C92: 1 | D92: =TRIM($A92) -> UL0769FGATAA043IH000002
A93: UL0859DBAABA312JA000003 | B93: XTD | C93: 1 | D93: =TRIM($A93) -> UL0859DBAABA312JA000003
A94: UL0926VHAABA122JA000013 | B94: XTH | C94: 1 | D94: =TRIM($A94) -> UL0926VHAABA122JA000013
A95: UL1002FHCSAA043IH000001 | B95: XTD | C95: 1 | D95: =TRIM($A95) -> UL1002FHCSAA043IH000001
A96: UL1002FILUAA022JA000005 | B96: XCG | C96: 1 | D96: =TRIM($A96) -> UL1002FILUAA022JA000005
A97: UL1002FIZMAA021BL000004 | B97: XCG | C97: 1 | D97: =TRIM($A97) -> UL1002FIZMAA021BL000004
A98: UL1047FBWNAA043IH000001 | B98: XTH | C98: 1 | D98: =TRIM($A98) -> UL1047FBWNAA043IH000001
A99: UL1095BSFFAA042JD000004 | B99: XTD | C99: 1 | D99: =TRIM($A99) -> UL1095BSFFAA042JD000004
A100: UL1153VFAR1A021BL000005 | B100: XTD | C100: 1 | D100: =TRIM($A100) -> UL1153VFAR1A021BL000005
A101: UL1153VFIR1A011BL000005 | B101: XCG | C101: 1 | D101: =TRIM($A101) -> UL1153VFIR1A011BL000005
... A155: UT3115FAPRAA042BD000010 | B155: XCG | C155: 1 | D155: =TRIM($A155) -> UT3115FAPRAA042BD000010
